Workbook

Sheet LAP.DAGING
C1: LAPORAN DAGING DAN RAWON FRESH TDN …....... | S1: PROSES TDN CIKARANG UTARA
B2: 46236
P3: DAGING PRESH | AA3: =SUM(AA6:AA56) -> 0 | AB3: DAGING PREMIUM | AE3: DAGING PREMIUM | AI3: RAWON FRESH | AS3: DAGING FRESH
B4: BAHAN | C4: HQ 41/44/45 FQ 65 | D4: : | E4: =S31 -> 120 | F4: x | G4: 102000 | H4: = | I4: =E4*G4 -> 12240000 | J4: =E4/E7 -> 1 | L4: 0.2 | R4: HQ 41/42/44/45 | U4: DG RNDG BEKU 1kg | X4: DAGING HUSUS | AB4: DG Prem 2 | AE4: FRIBOY | AI4: FQ 106/105/18/16/ | AL4: RAWON BEKU | AO4: RAWON FRESH 2 | AS4: FQ 60 /SHANK
C5: DG RNDG BEKU CURAH | E5: =V31 -> 0 | F5: x | G5: 96000 | H5: = | I5: =E5*G5 -> 0 | J5: =E5/E7 -> 0 | L5: 0.7 | O5: SUSUT | P5: TALLY | Q5: NETTO | R5: SUSUT | S5: TALLY | T5: NETTO | U5: SUSUT | V5: TALLY | W5: NETTO | X5: SUSUT | Y5: TALLY | Z5: NETTO | AB5: SUSUT | AC5: TALLY | AD5: NETTO | AE5: SUSUT | AF5: TALLY | AG5: NETTO | AI5: SUSUT | AJ5: TALLY | AK5: NETTO | AL5: SUSUT | AM5: TALLY | AN5: NETTO | AO5: SUSUT | AP5: TALLY | AQ5: NETTO | AS5: SUSUT | AT5: TALLY | AU5: NETTO
C6: DAGING HUSUS | E6: =Y31 -> 0 | F6: x | G6: 96000 | H6: = | I6: =E6*G6 -> 0 | O6: =P6-Q6 -> 0 | R6: =S6-T6 -> 0.3 | S6: 40 | T6: 39.7 | U6: =V6-W6 -> 0 | X6: =Y6-Z6 -> 0 | AB6: =AC6-AD6 -> 0 | AE6: =AF6-AG6 -> 0.21 | AF6: 23.21 | AG6: 23 | AI6: =AJ6-AK6 -> 0 | AL6: =AM6-AN6 -> 0 | AO6: =AP6-AQ6 -> 0.2 | AP6: 25 | AQ6: 24.8 | AS6: =AT6-AU6 -> 0.35 | AT6: 50.2 | AU6: 49.85
D7: TOTAL | E7: =SUM(E4:E6) -> 120 | I7: =SUM(I4:I6) -> 12240000 | O7: =P7-Q7 -> 0 | R7: =S7-T7 -> 0.1 | S7: 20 | T7: 19.9 | U7: =V7-W7 -> 0 | X7: =Y7-Z7 -> 0 | AB7: =AC7-AD7 -> 0 | AE7: =AF7-AG7 -> 0 | AI7: =AJ7-AK7 -> 0 | AL7: =AM7-AN7 -> 0 | AO7: =AP7-AQ7 -> 0 | AS7: =AT7-AU7 -> 0.6 | AT7: 50 | AU7: 49.4
B8: HASIL DAGING FRESH | C8: =C4 -> HQ 41/44/45 FQ 65 | D8: : | E8: =T31 -> 119.05 | F8: x | G8: =G4 -> 102000 | H8: = | I8: =E8*G8 -> 12143100 | O8: =P8-Q8 -> 0 | R8: =S8-T8 -> 0.15 | S8: 20 | T8: 19.85 | U8: =V8-W8 -> 0 | X8: =Y8-Z8 -> 0 | AB8: =AC8-AD8 -> 0 | AE8: =AF8-AG8 -> 0 | AI8: =AJ8-AK8 -> 0 | AL8: =AM8-AN8 -> 0 | AO8: =AP8-AQ8 -> 0 | AS8: =AT8-AU8 -> 0.44 | AT8: 25.19 | AU8: 24.75
C9: RENDANG BEKU CURAH | D9: : | E9: =W31 -> 0 | F9: x | G9: 102550 | H9: = | I9: =E9*G9 -> 0 | O9: =P9-Q9 -> 0 | R9: =S9-T9 -> 0.4 | S9: 40 | T9: 39.6 | U9: =V9-W9 -> 0 | X9: =Y9-Z9 -> 0 | AB9: =AC9-AD9 -> 0 | AE9: =AF9-AG9 -> 0 | AI9: =AJ9-AK9 -> 0 | AL9: =AM9-AN9 -> 0 | AO9: =AP9-AQ9 -> 0 | AS9: =AT9-AU9 -> 0
C10: DAGING HUSUS | E10: =Z31 -> 0 | F10: x | G10: 96000 | H10: = | I10: =E10*G10 -> 0 | O10: =P10-Q10 -> 0 | R10: =S10-T10 -> 0 | U10: =V10-W10 -> 0 | X10: =Y10-Z10 -> 0 | AB10: =AC10-AD10 -> 0 | AE10: =AF10-AG10 -> 0 | AI10: =AJ10-AK10 -> 0 | AL10: =AM10-AN10 -> 0 | AO10: =AP10-AQ10 -> 0 | AS10: =AT10-AU10 -> 0
D11: TOTAL | E11: =SUM(E8:E10) -> 119.05 | I11: =SUM(I8:I10) -> 12143100 | O11: =P11-Q11 -> 0 | R11: =S11-T11 -> 0 | U11: =V11-W11 -> 0 | X11: =Y11-Z11 -> 0 | AB11: =AC11-AD11 -> 0 | AE11: =AF11-AG11 -> 0 | AI11: =AJ11-AK11 -> 0 | AL11: =AM11-AN11 -> 0 | AO11: =AP11-AQ11 -> 0 | AS11: =AT11-AU11 -> 0
O12: =P12-Q12 -> 0 | R12: =S12-T12 -> 0 | U12: =V12-W12 -> 0 | X12: =Y12-Z12 -> 0 | AB12: =AC12-AD12 -> 0 | AE12: =AF12-AG12 -> 0 | AI12: =AJ12-AK12 -> 0 | AL12: =AM12-AN12 -> 0 | AO12: =AP12-AQ12 -> 0 | AS12: =AT12-AU12 -> 0
B13: MODAL DG FRESH - SUSUT JUAL | D13: =I7/(E11+E16) -> 104229.65 | O13: =P13-Q13 -> 0 | R13: =S13-T13 -> 0 | U13: =V13-W13 -> 0 | X13: =Y13-Z13 -> 0 | AB13: =AC13-AD13 -> 0 | AE13: =AF13-AG13 -> 0 | AI13: =AJ13-AK13 -> 0 | AL13: =AM13-AN13 -> 0 | AO13: =AP13-AQ13 -> 0 | AS13: =AT13-AU13 -> 0
O14: =P14-Q14 -> 0 | R14: =S14-T14 -> 0 | U14: =V14-W14 -> 0 | X14: =Y14-Z14 -> 0 | AB14: =AC14-AD14 -> 0 | AE14: =AF14-AG14 -> 0 | AI14: =AJ14-AK14 -> 0 | AL14: =AM14-AN14 -> 0 | AO14: =AP14-AQ14 -> 0 | AS14: =AT14-AU14 -> 0
D15: SUSUT PROSES | E15: =E11-E7 -> -0.95 | H15: : | I15: =I11-I7 -> -96900 | O15: =P15-Q15 -> 0 | R15: =S15-T15 -> 0 | U15: =V15-W15 -> 0 | X15: =Y15-Z15 -> 0 | AB15: =AC15-AD15 -> 0 | AE15: =AF15-AG15 -> 0 | AI15: =AJ15-AK15 -> 0 | AL15: =AM15-AN15 -> 0 | AO15: =AP15-AQ15 -> 0 | AS15: =AT15-AU15 -> 0
D16: SUSUT JUAL | E16: =-'SALES DAGING'!U4 -> -1.617 | H16: : | I16: =E16*98000 -> -158466 | O16: =P16-Q16 -> 0 | R16: =S16-T16 -> 0 | U16: =V16-W16 -> 0 | X16: =Y16-Z16 -> 0 | AB16: =AC16-AD16 -> 0 | AE16: =AF16-AG16 -> 0 | AI16: =AJ16-AK16 -> 0 | AL16: =AM16-AN16 -> 0 | AO16: =AP16-AQ16 -> 0 | AS16: =AT16-AU16 -> 0
D17: TOTAL SUSUT | E17: =SUM(E15:E16) -> -2.567 | I17: =SUM(I15:I16) -> -255366 | J17: =((E7-(E11+E16))/E7) -> 0.021391667 | O17: =P17-Q17 -> 0 | R17: =S17-T17 -> 0 | U17: =V17-W17 -> 0 | X17: =Y17-Z17 -> 0 | AB17: =AC17-AD17 -> 0 | AE17: =AF17-AG17 -> 0 | AI17: =AJ17-AK17 -> 0 | AL17: =AM17-AN17 -> 0 | AO17: =AP17-AQ17 -> 0 | AS17: =AT17-AU17 -> 0
D18: SELISIH BAHAN DAN HASIL | I18: =I11-I7 -> -96900 | L18: 110 | O18: =P18-Q18 -> 0 | R18: =S18-T18 -> 0 | U18: =V18-W18 -> 0 | X18: =Y18-Z18 -> 0 | AB18: =AC18-AD18 -> 0 | AE18: =AF18-AG18 -> 0 | AI18: =AJ18-AK18 -> 0 | AL18: =AM18-AN18 -> 0 | AO18: =AP18-AQ18 -> 0 | AS18: =AT18-AU18 -> 0
O19: =P19-Q19 -> 0 | R19: =S19-T19 -> 0 | U19: =V19-W19 -> 0 | X19: =Y19-Z19 -> 0 | AB19: =AC19-AD19 -> 0 | AE19: =AF19-AG19 -> 0 | AI19: =AJ19-AK19 -> 0 | AL19: =AM19-AN19 -> 0 | AO19: =AP19-AQ19 -> 0 | AS19: =AT19-AU19 -> 0
B20: BAHAN | C20: Daging Premium 2 | D20: : | E20: =AC31 -> 0 | F20: X | G20: 103000 | H20: = | I20: =E20*G20 -> 0 | J20: =E20/E22 -> 0 | L20: 0.7 | O20: =P20-Q20 -> 0 | R20: =S20-T20 -> 0 | U20: =V20-W20 -> 0 | X20: =Y20-Z20 -> 0 | AB20: =AC20-AD20 -> 0 | AE20: =AF20-AG20 -> 0 | AI20: =AJ20-AK20 -> 0 | AL20: =AM20-AN20 -> 0 | AO20: =AP20-AQ20 -> 0 | AS20: =AT20-AU20 -> 0
C21: Daging lokal | D21: : | E21: 71.485 | F21: x | G21: 127000 | H21: = | I21: =E21*G21 -> 9078595 | J21: =E21/E22 -> 1 | L21: 0.3 | O21: =P21-Q21 -> 0 | R21: =S21-T21 -> 0 | U21: =V21-W21 -> 0 | X21: =Y21-Z21 -> 0 | AB21: =AC21-AD21 -> 0 | AE21: =AF21-AG21 -> 0 | AI21: =AJ21-AK21 -> 0 | AL21: =AM21-AN21 -> 0 | AO21: =AP21-AQ21 -> 0 | AS21: =AT21-AU21 -> 0
D22: TOTAL | E22: =SUM(E20:E21) -> 71.485 | I22: =SUM(I20:I21) -> 9078595 | O22: =P22-Q22 -> 0 | R22: =S22-T22 -> 0 | U22: =V22-W22 -> 0 | X22: =Y22-Z22 -> 0 | AB22: =AC22-AD22 -> 0 | AE22: =AF22-AG22 -> 0 | AI22: =AJ22-AK22 -> 0 | AL22: =AM22-AN22 -> 0 | AO22: =AP22-AQ22 -> 0 | AS22: =AT22-AU22 -> 0
O23: =P23-Q23 -> 0 | R23: =S23-T23 -> 0 | U23: =V23-W23 -> 0 | X23: =Y23-Z23 -> 0 | AB23: =AC23-AD23 -> 0 | AE23: =AF23-AG23 -> 0 | AI23: =AJ23-AK23 -> 0 | AL23: =AM23-AN23 -> 0 | AO23: =AP23-AQ23 -> 0 | AS23: =AT23-AU23 -> 0
B24: HASIL | C24: Daging Premium 2 | D24: : | E24: =AD31 -> 0 | F24: X | G24: =G20 -> 103000 | H24: = | I24: =E24*G24 -> 0 | O24: =SUM(O6:O23) -> 0 | P24: =SUM(P6:P23) -> 0 | Q24: =SUM(Q6:Q23) -> 0 | R24: =S24-T24 -> 0 | U24: =V24-W24 -> 0 | X24: =Y24-Z24 -> 0 | AB24: =AC24-AD24 -> 0 | AE24: =AF24-AG24 -> 0 | AI24: =AJ24-AK24 -> 0 | AL24: =AM24-AN24 -> 0 | AO24: =AP24-AQ24 -> 0 | AS24: =AT24-AU24 -> 0
C25: Daging fresh lokal | D25: : | E25: 71.485 | F25: x | G25: =G21 -> 127000 | H25: = | I25: =E25*G25 -> 9078595 | R25: =S25-T25 -> 0 | U25: =V25-W25 -> 0 | X25: =Y25-Z25 -> 0 | AB25: =AC25-AD25 -> 0 | AE25: =AF25-AG25 -> 0 | AI25: =AJ25-AK25 -> 0 | AO25: =AP25-AQ25 -> 0 | AS25: =AT25-AU25 -> 0
D26: TOTAL | E26: =SUM(E24:E25) -> 71.485 | I26: =SUM(I24:I25) -> 9078595 | R26: =S26-T26 -> 0 | U26: =V26-W26 -> 0 | X26: =Y26-Z26 -> 0 | AB26: =AC26-AD26 -> 0 | AE26: =AF26-AG26 -> 0 | AI26: =AJ26-AK26 -> 0 | AO26: =AP26-AQ26 -> 0 | AS26: =AT26-AU26 -> 0
R27: =S27-T27 -> 0 | U27: =V27-W27 -> 0 | X27: =Y27-Z27 -> 0 | AB27: =AC27-AD27 -> 0 | AE27: =AF27-AG27 -> 0 | AI27: =AJ27-AK27 -> 0 | AO27: =AP27-AQ27 -> 0 | AS27: =AT27-AU27 -> 0
B28: MODAL DAGING PREM | D28: =(I22/(E26+E30)) -> 127752.38 | R28: =S28-T28 -> 0 | U28: =V28-W28 -> 0 | X28: =Y28-Z28 -> 0 | AB28: =AC28-AD28 -> 0 | AE28: =AF28-AG28 -> 0 | AI28: =AJ28-AK28 -> 0 | AO28: =AP28-AQ28 -> 0 | AS28: =AT28-AU28 -> 0
D29: SUSUT PROSES | E29: =E26-E22 -> 0 | H29: : | I29: =I22-I26 -> 0 | R29: =S29-T29 -> 0 | U29: =V29-W29 -> 0 | X29: =Y29-Z29 -> 0 | AB29: =AC29-AD29 -> 0 | AE29: =AF29-AG29 -> 0 | AI29: =AJ29-AK29 -> 0 | AO29: =AP29-AQ29 -> 0 | AS29: =AT29-AU29 -> 0
D30: SUSUT JUAL | E30: =-'SALES DAGING'!U5 -> -0.421 | H30: : | I30: =E30*100000 -> -42100 | J30: =((E22-(E26+E30))/E22) -> 0.0058893474 | R30: =S30-T30 -> 0 | U30: =V30-W30 -> 0 | X30: =Y30-Z30 -> 0 | AB30: =AC30-AD30 -> 0 | AE30: =AF30-AG30 -> 0 | AI30: =AJ30-AK30 -> 0 | AO30: =AP30-AQ30 -> 0 | AS30: =AT30-AU30 -> 0
D31: TOTAL SUSUT | E31: =SUM(E29:E30) -> -0.421 | I31: =SUM(I29:I30) -> -42100 | R31: =SUM(R6:R30) -> 0.95 | S31: =SUM(S6:S30) -> 120 | T31: =SUM(T6:T30) -> 119.05 | U31: =SUM(U6:U30) -> 0 | V31: =SUM(V6:V30) -> 0 | W31: =SUM(W6:W30) -> 0 | X31: =SUM(X6:X30) -> 0 | Y31: =SUM(Y6:Y30) -> 0 | Z31: =SUM(Z6:Z30) -> 0 | AB31: =SUM(AB6:AB30) -> 0 | AC31: =SUM(AC6:AC30) -> 0 | AD31: =SUM(AD6:AD30) -> 0 | AE31: =SUM(AE6:AE30) -> 0.21 | AF31: =SUM(AF6:AF30) -> 23.21 | AG31: =SUM(AG6:AG30) -> 23 | AI31: =SUM(AI6:AI30) -> 0 | AJ31: =SUM(AJ6:AJ30) -> 0 | AK31: =SUM(AK6:AK30) -> 0 | AL31: =SUM(AL6:AL30) -> 0 | AM31: =SUM(AM6:AM30) -> 0 | AN31: =SUM(AN6:AN30) -> 0 | AO31: =SUM(AO6:AO30) -> 0.2 | AP31: =SUM(AP6:AP30) -> 25 | AQ31: =SUM(AQ6:AQ30) -> 24.8 | AS31: =SUM(AS6:AS30) -> 1.39 | AT31: =SUM(AT6:AT30) -> 125.39 | AU31: =SUM(AU6:AU30) -> 124
D32: SELISIH BAHAN DAN HASIL | I32: =I22-I26 -> 0
B34: BAHAN | C34: FQ 105/106/18/19 | D34: : | E34: =AJ31 -> 0 | F34: x | G34: 86500 | H34: = | I34: =E34*G34 -> 0 | J34: =E34/E37 -> 0 | L34: 0.4 | S34: Bahan : | T34: =S31+V31+Y31+AF31+P24 -> 143.21 | V34: BAHAN | W34: =AJ31+AM31 -> 0 | Y34: BAHAN | Z34: =AM31+AP31 -> 25 | AC34: BAHAN | AD34: =AQ31 -> 24.8 | AF34: BAHAN | AG34: =AT31 -> 125.39
C35: DAGING RAWON BEKU | E35: =AM31 -> 0 | F35: x | G35: 75883.5 | H35: = | I35: =E35*G35 -> 0 | S35: Hasil 1 : | T35: =T31+W31+Z31+AG31+Q24 -> 142.05 | V35: HASIL 1 | W35: =AK31 -> 0 | Y35: HASIL 1 | Z35: =AN31 -> 0 | AB35: =W35+W36 -> 0 | AC35: HASIL 1 | AD35: =AR31 -> 0 | AE35: =Z35+Z36 -> 24.8 | AF35: HASIL 1 | AG35: =AU31 -> 124
C36: =AO4 -> RAWON FRESH 2 | D36: : | E36: =AP31 -> 25 | F36: x | G36: 84954 | H36: = | I36: =E36*G36 -> 2123850 | J36: =E36/E37 -> 1 | L36: 0.6 | S36: Susut : | T36: =R31+U31+X31+AE31 -> 1.16 | V36: HASIL 2 | W36: =AN31 -> 0 | Y36: HASIL 2 | Z36: =AQ31 -> 24.8 | AC36: SUSUT | AD36: =AP31 -> 25 | AF36: SUSUT | AG36: =AS31 -> 1.39
D37: TOTAL | E37: =SUM(E34:E36) -> 25 | I37: =SUM(I34:I36) -> 2123850 | V37: SUSUT | W37: =AI31+AL31+AO31 -> 0.2 | Y37: SUSUT | Z37: =AI31+AL31+AO31 -> 0.2
B39: HASIL RAWON FRESH | C39: =C34 -> FQ 105/106/18/19 | D39: : | E39: =AK31 -> 0 | F39: x | G39: =G34 -> 86500 | H39: = | I39: =E39*G39 -> 0 | J39: =(E37-E45)/E37 -> 0.008
C40: =C35 -> DAGING RAWON BEKU | E40: =AN31 -> 0 | F40: x | G40: 75883.5 | H40: = | I40: =E40*G40 -> 0
C41: =C36 -> RAWON FRESH 2 | D41: : | E41: =AQ31 -> 24.8 | F41: x | G41: =G36 -> 84954 | H41: = | I41: =E41*G41 -> 2106859.2
D42: TOTAL | E42: =SUM(E39:E41) -> 24.8 | I42: =SUM(I39:I41) -> 2106859.2
...

Sheet PROSES
B2: FORM PROSES PRODUKSI
B3: Hari : | C3: MINGGU
B4: Tanggal : | C4: 46236
B6: Nomor | C6: 1 | D6: 2 | E6: 3 | F6: 4 | G6: 5 | H6: 6 | I6: 7 | J6: 8 | K6: 9 | L6: 10 | M6: 11 | N6: 12 | O6: 13 | P6: 14 | Q6: 15 | R6: 16 | S6: 17 | T6: 18 | U6: 19 | V6: 20 | W6: TOTAL | Y6: TOTAL BAHAN
B7: Bahan | C7: =LAP.DAGING!S31 -> 120 | D7: =LAP.DAGING!V31 -> 0 | E7: =LAP.DAGING!Y31 -> 0 | G7: =LAP.DAGING!AJ31 -> 0 | H7: =LAP.DAGING!AP31 -> 25 | I7: =LAP.DAGING!AC31 -> 0 | J7: =LAP.DAGING!AF31 -> 23.21 | K7: =LAP.DAGING!AT31 -> 125.39 | W7: =SUM(C7:V7) -> 293.6 | Y7: =W7 -> 293.6 | AA7: =Y7-Y10 -> 2.75
B8: D.sapi p. rdang | C8: =LAP.DAGING!T31 -> 119.05 | D8: =LAP.DAGING!W31 -> 0 | E8: =LAP.DAGING!Z31 -> 0 | W8: =SUM(C8:V8) -> 119.05
B9: D premium lokal | I9: =LAP.DAGING!AD31 -> 0 | J9: =LAP.DAGING!AG31 -> 23 | W9: =SUM(C9:V9) -> 23 | Y9: TOTAL BERSIH
W10: =SUM(C10:V10) -> 0 | Y10: =W8+W9+W11+W12 -> 290.85
B11: D fresh ekonomis | K11: =LAP.DAGING!AU31 -> 124 | W11: =SUM(C11:V11) -> 124
B12: Rawon Curah | G12: =LAP.DAGING!AK31 -> 0 | H12: =LAP.DAGING!AQ31 -> 24.8 | W12: =SUM(C12:V12) -> 24.8
B13: Urat Triming | W13: =SUM(C13:V13) -> 0
W14: =W7-SUM(W8:W13) -> 2.75
B16: HASIL PRODUKSI RENDANG FRESH | E16: = | F16: =W8 -> 119.05 | G16: KG
C17: DAGING PREMIUM | E17: = | F17: 0 | G17: KG
B18: BERSIH DAGING RENDANG FRESH | E18: = | F18: =F16-F17 -> 119.05 | G18: KG
B20: Total Bahan | W20: =W7 -> 293.6
B21: Total D. Sapi pot Rendang | W21: =W8 -> 119.05
B22: Tot D Premium lokal | W22: =W9 -> 23
B23: Total Sankle | W23: =W10 -> 0
B24: D fresh ekonomis | W24: =W11 -> 124
B25: Total Rawon | W25: =W12 -> 24.8
B26: Total Urat triming | W26: =W13 -> 0
B27: SUSUT | W27: =W20-SUM(W21:W26) -> 2.75

Sheet SALES DAGING
B1: LAPORAN STOCK DAGING TDN CIKARANG UTARA TGL 02 AGUSTUS 2026
B2: Tanggal | C2: Stock Awal (Pagi) | D2: Keterangan | E2: Tanggal | F2: BAHAN PRODUKSI | G2: Masuk ke Toko | H2: ADJ IN | I2: ADJ OUT | J2: ADJ OUT | K2: Hasil | L2: Keterangan | M2: Total Real ( Kg ) | N2: Penjualan | O2: Keterangan | P2: Stock Akhir by Sistem | Q2: Tanggal | R2: Giling 500 gr (in kg) | S2: Stock Akhir Real (Kg) | T2: Keterangan | U2: Penyusutan
B3: 214 | C3: 18.636 | D3: Daging Rendang Shankle | E3: =B3+1 -> 215 | F3: =PROSES!Y7 -> 293.6 | G3: =PROSES!Y10 -> 290.85 | H3: 0 | K3: =PROSES!W24 -> 124 | L3: Daging Rendang Shankle | M3: =K3+C3-I3+H3-J3 -> 142.636 | N3: 135.012 | O3: Daging Rendang Shankle | P3: =M3-N3 -> 7.624 | Q3: =E3 -> 215 | R3: 0 | S3: 5.829 | T3: Daging Fresh ekonomis | U3: =P3-S3-R3 -> 1.795
C4: 120.044 | D4: D.s. pot. rdang | H4: 0 | I4: =H5+H6+H7+H3 -> 0 | K4: =PROSES!W21 -> 119.05 | L4: D.sapi p. rdang | M4: =K4+C4-I4+H4-J4 -> 239.094 | N4: 100.596 | O4: D.sapi p. rdang | P4: =M4-N4 -> 138.498 | S4: 136.881 | T4: D.sapi pot. rdang | U4: =P4-S4-R4 -> 1.617
C5: 26.56 | D5: D premium lokal | H5: 0 | I5: 0 | K5: =PROSES!W22 -> 23 | L5: D Premium lokal | M5: =K5+C5-I5+H5-J5 -> 49.56 | N5: 46.11 | O5: D Premium lokal | P5: =M5-N5 -> 3.45 | S5: 3.029 | T5: D Premium lokal | U5: =P5-S5-R5 -> 0.421
C6: 0 | D6: D.r. fresh member | H6: 0 | K6: 0 | L6: D.r. fresh member | M6: =K6+C6-I6+H6-J6 -> 0 | N6: 0 | O6: D.r. fresh member | P6: =M6-N6 -> 0 | S6: 0 | T6: D.r. fresh member | U6: =P6-S6-R6 -> 0
C7: 9.569 | D7: Rawon Curah | H7: 0 | I7: 0 | K7: =PROSES!W25 -> 24.8 | L7: Rawon Curah | M7: =K7+C7-I7+H7-J7 -> 34.369 | N7: 30.258 | O7: Rawon Curah | P7: =M7-N7 -> 4.111 | S7: 3.592 | T7: Rawon Curah | U7: =P7-S7-R7 -> 0.519
C8: 155.414 | F8: SELISIH | G8: =F3-G3 -> 2.75 | J8: =SUM(J3:J7) -> 0 | K8: =SUM(K3:K7) -> 290.85 | M8: =K8+C8-I8+H8-J8 -> 446.264 | N8: =SUM(N3:N7) -> 311.976 | P8: =SUM(P3:P7) -> 153.683 | S8: =SUM(S3:S7) -> 149.331 | U8: =SUM(U3:U7) -> 4.352
C10: NOTE : | D10: ITEM DAGING SAPI POT RENDANG TERJUAL KE DG PREM LOKAL : | I10: 0 | K10: KG
D11: ITEM DAGING PREM LOKAL TERJUAL KE DAGING SAPI POT RENDANG : | I11: 0 | K11: KG
D12: ITEM DAGING SAPI POT RENDANG TERJUAL KE DG FRESH MEMBER : | I12: 0 | K12: KG
J166: MASIH AKTIF DAN RUTIN BERBELANJA DI TDN CIKUT
U977: L Dewasa
